<?xml version="1.0"?>
<robot name="policy_inference_core_robot">
  <link name="base_link"/>
  <link name="tool_link"/>

  <joint name="joint1" type="revolute">
    <parent link="base_link"/>
    <child link="tool_link"/>
    <origin xyz="0 0 0" rpy="0 0 0"/>
    <axis xyz="0 0 1"/>
    <limit lower="-3.14" upper="3.14" effort="10.0" velocity="10.0"/>
  </joint>

  <ros2_control name="PolicyInferenceDemoSystem" type="system">
    <hardware>
      <plugin>mock_components/GenericSystem</plugin>
    </hardware>

    <joint name="joint1">
      <command_interface name="position"/>
      <state_interface name="position"/>
      <state_interface name="velocity"/>
    </joint>
  </ros2_control>
</robot>

